Workbook

Sheet 2016
A1: S/N | B1: State | C1: January (Net) | D1: January (Gross) | E1: February (Net) | F1: February (Gross) | G1: March (Net) | H1: March (Gross) | I1: April (Net) | J1: April (Gross) | K1: May (Net) | L1: May (Gross) | M1: June (Net) | N1: June (Gross) | O1: July (Net) | P1: July (Gross) | Q1: August (Net) | R1: August (Gross) | S1: September,(Net) | T1: September,(Gross) | U1: October.(Net) | V1: October (Gross) | W1: November (Net) | X1: November (Gross) | Y1: December (Net) | Z1: December (Gross) | AA1: Total Net | AB1: Total IGR | AC1: Total Net USD | AD1: Total IGR USD
A2: 1 | B2: Abia | C2: 2.2776426e+09 | D2: 2.661403e+09 | E2: 1.9384472e+09 | F2: 2.2942563e+09 | G2: 2.0563566e+09 | H2: 2.1979028e+09 | I2: 2.0800235e+09 | J2: 2.1315972e+09 | K2: 1.9239825e+09 | L2: 2.2523842e+09 | M2: 3.5509245e+09 | N2: 3.8793262e+09 | O2: 3.2198155e+09 | P2: 3.5598836e+09 | Q2: 3.0074505e+09 | R2: 3.3515434e+09 | S2: 2.6375943e+09 | T2: 2.9816871e+09 | U2: 2.7960548e+09 | V2: 3.1359154e+09 | W2: 2.5325397e+09 | X2: 2.8724003e+09 | Y2: 2.5370166e+09 | Z2: 2.9074758e+09 | AA2: =SUM(C2,E2,G2,I2,K2,M2,O2,Q2,S2,U2,W2,Y2) -> 3.0557848e+10 | AB2: =AA2+Z2 -> 3.3465324e+10 | AC2: =AA2/253 -> 1.2078201e+08 | AD2: =AB2/253 -> 1.3227401e+08
A3: 2 | B3: Adamawa | C3: 2.2230185e+09 | D3: 2.5741739e+09 | E3: 2.0320397e+09 | F3: 2.3831951e+09 | G3: 2.0194574e+09 | H3: 2.1302282e+09 | I3: 2.0197201e+09 | J3: 2.0405183e+09 | K3: 1.8287582e+09 | L3: 2.1799136e+09 | M3: 3.5355466e+09 | N3: 3.886702e+09 | O3: 3.0450583e+09 | P3: 3.3962137e+09 | Q3: 3.1476096e+09 | R3: 3.5182343e+09 | S3: 2.5405235e+09 | T3: 2.9111482e+09 | U3: 2.523857e+09 | V3: 2.8944817e+09 | W3: 2.3495521e+09 | X3: 2.7201768e+09 | Y3: 2.4547963e+09 | Z3: 2.825421e+09 | AA3: =SUM(C3,E3,G3,I3,K3,M3,O3,Q3,S3,U3,W3,Y3) -> 2.9719937e+10 | AB3: =AA3+Z3 -> 3.2545358e+10 | AC3: =AA3/253 -> 1.1747011e+08 | AD3: =AB3/253 -> 1.2863778e+08
A4: 3 | B4: Akwa Ibom | C4: 8.5566838e+09 | D4: 9.6888125e+09 | E4: 8.9455421e+09 | F4: 1.0077671e+10 | G4: 8.2684255e+09 | H4: 8.8030915e+09 | I4: 6.5674216e+09 | J4: 7.0091795e+09 | K4: 6.8475737e+09 | L4: 8.0323886e+09 | M4: 9.1610911e+09 | N4: 1.0345906e+10 | O4: 1.1264224e+10 | P4: 1.2322363e+10 | Q4: 1.3854814e+10 | R4: 1.4934351e+10 | S4: 8.7164677e+09 | T4: 9.8910142e+09 | U4: 6.1327649e+09 | V4: 7.2123112e+09 | W4: 5.3752065e+09 | X4: 6.4547528e+09 | Y4: 9.1241299e+09 | Z4: 1.0203676e+10 | AA4: =SUM(C4,E4,G4,I4,K4,M4,O4,Q4,S4,U4,W4,Y4) -> 1.0281435e+11 | AB4: =AA4+Z4 -> 1.1301802e+11 | AC4: =AA4/253 -> 4.0638081e+08 | AD4: =AB4/253 -> 4.4671155e+08
A5: 4 | B5: Anambra | C5: 2.5180022e+09 | D5: 2.6486353e+09 | E5: 2.3136767e+09 | F5: 2.4443098e+09 | G5: 2.0614108e+09 | H5: 2.1920439e+09 | I5: 2.0784786e+09 | J5: 2.1191391e+09 | K5: 2.1168077e+09 | L5: 2.2474407e+09 | M5: 3.8283189e+09 | N5: 3.958952e+09 | O5: 3.332951e+09 | P5: 3.4635848e+09 | Q5: 3.4398625e+09 | R5: 3.5943602e+09 | S5: 2.8146224e+09 | T5: 2.9691201e+09 | U5: 2.8086915e+09 | V5: 2.9631892e+09 | W5: 2.6900397e+09 | X5: 2.8445374e+09 | Y5: 2.7382366e+09 | Z5: 2.8927343e+09 | AA5: =SUM(C5,E5,G5,I5,K5,M5,O5,Q5,S5,U5,W5,Y5) -> 3.2741099e+10 | AC5: =AA5/253 -> 1.2941146e+08 | AD5: =AB5/253 -> 0
A6: 5 | B6: Bauchi | C6: 2.5570368e+09 | D6: 3.0616633e+09 | E6: 2.2572019e+09 | F6: 2.8159952e+09 | G6: 2.1523572e+09 | H6: 2.5119153e+09 | I6: 2.048627e+09 | J6: 2.4081851e+09 | K6: 1.9652552e+09 | L6: 2.5779099e+09 | M6: 4.0092748e+09 | N6: 4.6219295e+09 | O6: 3.4354443e+09 | P6: 4.0480991e+09 | Q6: 3.5213066e+09 | R6: 4.1667945e+09 | S6: 2.3590718e+09 | T6: 3.4509762e+09 | U6: 2.7893869e+09 | V6: 3.4348747e+09 | W6: 2.442013e+09 | X6: 3.2470567e+09 | Y6: 2.4302651e+09 | Z6: 3.32395e+09 | AA6: =SUM(C6,E6,G6,I6,K6,M6,O6,Q6,S6,U6,W6,Y6) -> 3.1967241e+10 | AB6: =AA6+Z6 -> 3.5291191e+10 | AC6: =AA6/253 -> 1.2635273e+08 | AD6: =AB6/253 -> 1.3949087e+08
A7: 6 | B7: Bayelsa | C7: 2.9843265e+09 | D7: 6.0328135e+09 | E7: 2.165039e+09 | F7: 5.4994356e+09 | G7: 2.4233059e+09 | H7: 4.8573118e+09 | I7: 3.3965037e+09 | J7: 4.9527548e+09 | K7: 2.816868e+09 | L7: 5.1257113e+09 | M7: 4.9824191e+09 | N7: 7.2912624e+09 | O7: 6.6315836e+09 | P7: 8.9404369e+09 | Q7: 7.6026974e+09 | R7: 9.9200062e+09 | S7: 6.3559369e+09 | T7: 8.7298849e+09 | U7: 8.1153594e+09 | V7: 1.0432632e+10 | W7: 6.2887502e+09 | X7: 8.606059e+09 | Y7: 6.644847e+09 | Z7: 8.04694e+09 | AA7: =SUM(C7,E7,G7,I7,K7,M7,O7,Q7,S7,U7,W7,Y7) -> 6.0407637e+10 | AB7: =AA7+Z7 -> 6.8454577e+10 | AC7: =AA7/253 -> 2.3876536e+08 | AD7: =AB7/253 -> 2.7057145e+08
A8: 7 | B8: Benue | C8: 2.1029361e+09 | D8: 2.8701126e+09 | E8: 1.8015765e+09 | F8: 2.6587257e+09 | G8: 1.7194458e+09 | H8: 2.3783535e+09 | I8: 1.7421465e+09 | J8: 2.3110816e+09 | K8: 1.5349603e+09 | L8: 2.4501698e+09 | M8: 3.8863835e+09 | N8: 4.4332015e+09 | O8: 3.2616376e+09 | P8: 3.0084556e+09 | Q8: 3.3760748e+09 | R8: 3.9284671e+09 | S8: 2.7256926e+09 | T8: 3.2780849e+09 | U8: 2.7009933e+09 | V8: 3.2533857e+09 | W8: 2.4470553e+09 | X8: 3.0507854e+09 | Y8: 2.5443619e+09 | Z8: 3.148092e+09 | AA8: =SUM(C8,E8,G8,I8,K8,M8,O8,Q8,S8,U8,W8,Y8) -> 2.9843264e+10 | AB8: =AA8+Z8 -> 3.2991356e+10 | AC8: =AA8/253 -> 1.1795757e+08 | AD8: =AB8/253 -> 1.3040062e+08
A9: 8 | B9: Borno | C9: 2.8711257e+09 | D9: 3.0800159e+09 | E9: 2.6652101e+09 | F9: 2.8741004e+09 | G9: 2.4110653e+09 | H9: 2.5508558e+09 | I9: 2.4219381e+09 | J9: 2.4350529e+09 | K9: 2.1476006e+09 | L9: 2.6110821e+09 | M9: 4.2600407e+09 | N9: 4.7235222e+09 | O9: 3.6647473e+09 | P9: 4.1282288e+09 | Q9: 3.9063184e+09 | R9: 4.2468128e+09 | S9: 3.2214927e+09 | T9: 3.561987e+09 | U9: 3.2083732e+09 | V9: 3.5488676e+09 | W9: 2.9285037e+09 | X9: 3.2689981e+09 | Y9: 3.0351035e+09 | Z9: 3.3755979e+09 | AA9: =SUM(C9,E9,G9,I9,K9,M9,O9,Q9,S9,U9,W9,Y9) -> 3.6741519e+10 | AB9: =AA9+Z9 -> 4.0117117e+10 | AC9: =AA9/253 -> 1.452234e+08 | AD9: =AB9/253 -> 1.5856568e+08
A10: 9 | B10: Cross River | C10: 1.0695907e+09 | D10: 2.5520125e+09 | E10: 9.6749496e+08 | F10: 2.3728142e+09 | G10: 1.2299359e+09 | H10: 2.1259965e+09 | I10: 1.1842772e+09 | J10: 2.0303653e+09 | K10: 8.0406098e+08 | L10: 2.1785646e+09 | M10: 2.6516795e+09 | N10: 4.0261831e+09 | O10: 1.9879181e+09 | P10: 3.3945565e+09 | Q10: 2.0420408e+09 | R10: 3.5070092e+09 | S10: 1.4370766e+09 | T10: 2.9020452e+09 | U10: 1.4333245e+09 | V10: 2.8982929e+09 | W10: 1.2697484e+09 | X10: 2.7347167e+09 | Y10: 1.2716612e+09 | Z10: 2.8307456e+09 | AA10: =SUM(C10,E10,G10,I10,K10,M10,O10,Q10,S10,U10,W10,Y10) -> 1.7348809e+10 | AB10: =AA10+Z10 -> 2.0179555e+10 | AC10: =AA10/253 -> 68572367 | AD10: =AB10/253 -> 79761085
A11: 10 | B11: Delta | C11: 6.0621621e+09 | D11: 8.5766569e+09 | E11: 6.5204737e+09 | F11: 8.9082926e+09 | G11: 6.4271199e+09 | H11: 7.7966035e+09 | I11: 4.2077677e+09 | J11: 5.4505755e+09 | K11: 2.8909135e+09 | L11: 5.1507167e+09 | M11: 5.1110055e+09 | N11: 7.3708088e+09 | O11: 5.9843356e+09 | P11: 8.2441388e+09 | Q11: 7.3919405e+09 | R11: 9.6613238e+09 | S11: 5.6360269e+09 | T11: 7.9557738e+09 | U11: 8.092987e+09 | V11: 1.036237e+10 | W11: 6.3246707e+09 | X11: 8.5940541e+09 | Y11: 6.1724923e+09 | Z11: 8.4418757e+09 | AA11: =SUM(C11,E11,G11,I11,K11,M11,O11,Q11,S11,U11,W11,Y11) -> 7.0821896e+10 | AB11: =AA11+Z11 -> 7.9263771e+10 | AC11: =AA11/253 -> 2.7992844e+08 | AD11: =AB11/253 -> 3.1329554e+08
A12: 11 | B12: Ebonyi | C12: 2.1671497e+09 | D12: 2.3020052e+09 | E12: 1.9931027e+09 | F12: 2.1267289e+09 | G12: 1.7811665e+09 | H12: 1.906834e+09 | I12: 1.7899769e+09 | J12: 1.8247269e+09 | K12: 1.8435737e+09 | L12: 1.9754804e+09 | M12: 3.4074414e+09 | N12: 3.539348e+09 | O12: 2.9153567e+09 | P12: 3.0492236e+09 | Q12: 2.9939936e+09 | R12: 3.1431265e+09 | S12: 2.4750864e+09 | T12: 2.6207539e+09 | U12: 2.4733309e+09 | V12: 2.6161651e+09 | W12: 2.2831452e+09 | X12: 2.4468155e+09 | Y12: 2.37356e+09 | Z12: 2.5322601e+09 | AA12: =SUM(C12,E12,G12,I12,K12,M12,O12,Q12,S12,U12,W12,Y12) -> 2.8496884e+10 | AB12: =AA12+Z12 -> 3.1029144e+10 | AC12: =AA12/253 -> 1.126359e+08 | AD12: =AB12/253 -> 1.2264484e+08
A13: 12 | B13: Edo | C13: 2.0946704e+09 | D13: 3.1482648e+09 | E13: 1.9970076e+09 | F13: 3.0528482e+09 | G13: 1.8817561e+09 | H13: 2.6401155e+09 | I13: 1.6704147e+09 | J13: 2.3388014e+09 | K13: 1.1626459e+09 | L13: 2.2035845e+09 | M13: 2.9702904e+09 | N13: 4011228991 | O13: 2587720121 | P13: 3.6286587e+09 | Q13: 2.5451178e+09 | R13: 3.6230284e+09 | S13: 1.9772099e+09 | T13: 3.0570576e+09 | U13: 2.1743121e+09 | V13: 3.1830898e+09 | W13: 1.9587368e+09 | X13: 2.9675145e+09 | Y13: 2.1161579e+09 | Z13: 3.1019894e+09 | AA13: =SUM(C13,E13,G13,I13,K13,M13,O13,Q13,S13,U13,W13,Y13) -> 2.513604e+10 | AB13: =AA13+Z13 -> 2.8238029e+10 | AC13: =AA13/253 -> 99351935 | AD13: =AB13/253 -> 1.1161276e+08
A14: 13 | B14: Ekiti | C14: 1.3769763e+09 | D14: 2.3056408e+09 | E14: 1.0844697e+09 | F14: 2.1519669e+09 | G14: 1.1870894e+09 | H14: 1.9200274e+09 | I14: 1.2668141e+09 | J14: 1.8609194e+09 | K14: 9.0360295e+08 | L14: 1.9711001e+09 | M14: 2.4227614e+09 | N14: 3.4902586e+09 | O14: 2.046393e+09 | P14: 3.0650301e+09 | Q14: 2.1680593e+09 | R14: 3.1629677e+09 | S14: 1.6327591e+09 | T14: 2.6276675e+09 | U14: 1.5752296e+09 | V14: 2.6112505e+09 | W14: 1.4506414e+09 | X14: 2.4625031e+09 | Y14: 1.5485763e+09 | Z14: 2.5324748e+09 | AA14: =SUM(C14,E14,G14,I14,K14,M14,O14,Q14,S14,U14,W14,Y14) -> 1.8663372e+10 | AB14: =AA14+Z14 -> 2.1195847e+10 | AC14: =AA14/253 -> 73768271 | AD14: =AB14/253 -> 83778052
A15: 14 | B15: Enugu | C15: 2.3722003e+09 | D15: 2.6091462e+09 | E15: 2.2077952e+09 | F15: 2.4447412e+09 | G15: 2.0917232e+09 | H15: 2.2121734e+09 | I15: 2.0497785e+09 | J15: 2.0802561e+09 | K15: 2.0031379e+09 | L15: 2.2400839e+09 | M15: 3.7229106e+09 | N15: 3.9598566e+09 | O15: 3.2098295e+09 | P15: 3.4487754e+09 | Q15: 3.3495575e+09 | R15: 3.6090642e+09 | S15: 2.691129e+09 | T15: 2.9506357e+09 | U15: 2.4028608e+09 | V15: 2.9565727e+09 | W15: 2.2110144e+09 | X15: 2.7647262e+09 | Y15: 2.4758035e+09 | Z15: 2.8824128e+09 | AA15: =SUM(C15,E15,G15,I15,K15,M15,O15,Q15,S15,U15,W15,Y15) -> 3.078774e+10 | AB15: =AA15+Z15 -> 3.3670153e+10 | AC15: =AA15/253 -> 1.2169067e+08 | AD15: =AB15/253 -> 1.3308361e+08
A16: 15 | B16: Gombe | C16: 1.5952516e+09 | D16: 2.3903636e+09 | E16: 1.4582574e+09 | F16: 2.2533694e+09 | G16: 1.2582555e+09 | H16: 1.9807155e+09 | I16: 1.2925867e+09 | J16: 1.9250741e+09 | K16: 1.2375655e+09 | L16: 2.0326775e+09 | M16: 2.8864573e+09 | N16: 3.6815693e+09 | O16: 2.3859497e+09 | P16: 3.1810817e+09 | Q16: 2.6170593e+09 | R16: 3.3036123e+09 | S16: 2.0321957e+09 | T16: 2.7187387e+09 | U16: 2.0695171e+09 | V16: 2.7560601e+09 | W16: 1.8370677e+09 | X16: 2.5437002e+09 | Y16: 1.9295771e+09 | Z16: 2.630277e+09 | AA16: =SUM(C16,E16,G16,I16,K16,M16,O16,Q16,S16,U16,W16,Y16) -> 2.2599741e+10 | AB16: =AA16+Z16 -> 2.5230018e+10 | AC16: =AA16/253 -> 89327038 | AD16: =AB16/253 -> 99723390
A17: 16 | B17: Imo | C17: 2.2998711e+09 | D17: 2911146156 | E17: 1.630698e+09 | F17: 2.6057314e+09 | G17: 2.3377946e+09 | H17: 2.4005975e+09 | I17: 2.2678049e+09 | J17: 2.3306078e+09 | K17: 1.8728798e+09 | L17: 2.4738377e+09 | M17: 3.7542445e+09 | N17: 4.3552024e+09 | O17: 3.0266094e+09 | P17: 3.809419e+09 | Q17: 2.9780718e+09 | R17: 3.8660343e+09 | S17: 2.3125023e+09 | T17: 3.2018838e+09 | U17: 2.5037092e+09 | V17: 3.3802844e+09 | W17: 2.5278171e+09 | X17: 3.4043923e+09 | Y17: 2.3721471e+09 | Z17: 3.2487223e+09 | AA17: =SUM(C17,E17,G17,I17,K17,M17,O17,Q17,S17,U17,W17,Y17) -> 2.988415e+10 | AB17: =AA17+Z17 -> 3.3132872e+10 | AC17: =AA17/253 -> 1.1811917e+08 | AD17: =AB17/253 -> 1.3095997e+08
... A37: 36 | B37: Zamfara | C37: 1.6227776e+09 | D37: 2.5529657e+09 | E37: 1.4718578e+09 | F37: 2.4020458e+09 | G37: 1.5363072e+09 | H37: 2.1333792e+09 | I37: 1.5298971e+09 | J37: 2.0369964e+09 | K37: 1.2427502e+09 | L37: 2.1729383e+09 | M37: 2.9474691e+09 | N37: 3.8776572e+09 | O37: 2.3789111e+09 | P37: 3.4024983e+09 | Q37: 2.5844179e+09 | R37: 3.5192614e+09 | S37: 2.0027943e+09 | T37: 2.9376378e+09 | U37: 1.9496971e+09 | V37: 2.8845406e+09 | W37: 1.7884766e+09 | X37: 2.7233201e+09 | Y37: 1.8629922e+09 | Z37: 2.7978356e+09 | AA37: =SUM(C37,E37,G37,I37,K37,M37,O37,Q37,S37,U37,W37,Y37) -> 2.2918348e+10 | AB37: =AA37+Z37 -> 2.5716184e+10 | AC37: =AA37/253 -> 90586357 | AD37: =AB37/253 -> 1.01645e+08
A38: 37 | B38: FCT | C38: 3.4037444e+09 | E38: 3.1618877e+09 | G38: 2.8080327e+09 | I38: 2.6798664e+09 | K38: 2.8844091e+09 | M38: 5.2889554e+09 | O38: 4.6077656e+09 | Q38: 4.705974e+09 | S38: 3.9049841e+09 | U38: 3.8652163e+09 | W38: 3.5859578e+09 | Y38: 3.6953384e+09 | AA38: =SUM(C38,E38,G38,I38,K38,M38,O38,Q38,S38,U38,W38,Y38) -> 4.4592132e+10 | AC38: =AA38/253 -> 1.7625349e+08 | AD38: =AB38/253 -> 0
AA39: =SUM(AA2:AA38) -> 1.3499746e+12 | AC39: =AA39/253 -> 5.3358681e+09

Sheet 2017
A1: S/N | B1: State | C1: January (Net) | D1: January (Gross) | E1: February (Net) | F1: February (Gross) | G1: March (Net) | H1: March (Gross) | I1: April (Net) | J1: April (Gross) | K1: May (Net) | L1: May (Gross) | M1: June (Net) | N1: June (Gross) | O1: July (Net) | P1: July (Gross) | Q1: August (Net) | R1: August (Gross) | S1: September (Net) | T1: September (Gross) | U1: October (Net) | V1: October (Gross) | W1: November (Net) | X1: November (Gross) | Y1: December (Net) | Z1: December (Gross) | AA1: Total Net | AB1: Total IGR | AC1: Total Net USD | AD1: Total IGR USD
A2: 1 | B2: Abia | C2: 3.036639e+09 | D2: 3.4071963e+09 | E2: 2.8425955e+09 | F2: 3.2150886e+09 | G2: 2.8652138e+09 | H2: 3.38174e+09 | I2: 2.589011e+09 | J2: 3.1055371e+09 | K2: 2.8260502e+09 | L2: 3.3425764e+09 | M2: 4.1177434e+09 | N2: 4.562253e+09 | O2: 3.0134931e+09 | P2: 3.4940933e+09 | Q2: 4.0383687e+09 | R2: 4.5170332e+09 | S2: 3.523603e+09 | T2: 3.9870314e+09 | U2: 3.4832798e+09 | V2: 3.9467082e+09 | W2: 4.0036888e+09 | X2: 4.4671172e+09 | Y2: 4.3587676e+09 | Z2: 4.822196e+09 | AA2: =SUM(C2,E2,G2,I2,K2,M2,O2,Q2,S2,U2,W2,Y2) -> 4.0698454e+10 | AB2: 1.4917142e+10 | AC2: =AA2/305 -> 1.3343755e+08 | AD2: =AB2/305 -> 48908662
A3: 2 | B3: Adamawa | C3: 2.8298725e+09 | D3: 3.2122506e+09 | E3: 2.5102476e+09 | F3: 2.8926257e+09 | G3: 2.8123955e+09 | H3: 3.1947736e+09 | I3: 2.4985244e+09 | J3: 2.8809025e+09 | K3: 2.8081139e+09 | L3: 3.190492e+09 | M3: 4.1177035e+09 | N3: 4.5000816e+09 | O3: 2.875536e+09 | P3: 3.2416588e+09 | Q3: 4.0209348e+09 | R3: 4.3870576e+09 | S3: 3.4353394e+09 | T3: 3.8014622e+09 | U3: 3.2931014e+09 | V3: 3.6592242e+09 | W3: 3.7798968e+09 | X3: 4.1460196e+09 | Y3: 4.0600442e+09 | Z3: 4.426167e+09 | AA3: =SUM(C3,E3,G3,I3,K3,M3,O3,Q3,S3,U3,W3,Y3) -> 3.904171e+10 | AB3: 6.2013696e+09 | AC3: =AA3/305 -> 1.2800561e+08 | AD3: =AB3/305 -> 20332359
A4: 3 | B4: Akwa Ibom | C4: 1.3084006e+10 | D4: 1.4175214e+10 | E4: 1.2667764e+10 | F4: 1.3758972e+10 | G4: 1.3612313e+10 | H4: 1.4703521e+10 | I4: 1.109213e+10 | J4: 1.2183338e+10 | K4: 9.3130251e+09 | L4: 1.0404233e+10 | M4: 1.196855e+10 | N4: 1.3059758e+10 | O4: 9.9698075e+09 | P4: 1.1058523e+10 | Q4: 1.294792e+10 | R4: 1.4036636e+10 | S4: 1.293387e+10 | T4: 1.4022586e+10 | U4: 1.3168152e+10 | V4: 1.4256868e+10 | W4: 1.3733278e+10 | X4: 1.4821994e+10 | Y4: 1.6558937e+10 | Z4: 1.7647653e+10 | AA4: =SUM(C4,E4,G4,I4,K4,M4,O4,Q4,S4,U4,W4,Y4) -> 1.5104975e+11 | AB4: 1.5956354e+10 | AC4: =AA4/305 -> 4.9524509e+08 | AD4: =AB4/305 -> 52315915
A5: 4 | B5: Anambra | C5: 3.1297265e+09 | D5: 3.2762856e+09 | E5: 2.8290081e+09 | F5: 2.9755672e+09 | G5: 3.0998787e+09 | H5: 3.2464378e+09 | I5: 2.8310631e+09 | J5: 2.9776221e+09 | K5: 3.2355669e+09 | L5: 3.382126e+09 | M5: 4.4492845e+09 | N5: 4.5958435e+09 | O5: 3.1900718e+09 | P5: 3.3334856e+09 | Q5: 4.3337583e+09 | R5: 4.4771722e+09 | S5: 3.7429662e+09 | T5: 3.8863801e+09 | U5: 3.6953635e+09 | V5: 3.8387773e+09 | W5: 4.0633139e+09 | X5: 4.2067278e+09 | Y5: 4.3718194e+09 | Z5: 4.4981842e+09 | AA5: =SUM(C5,E5,G5,I5,K5,M5,O5,Q5,S5,U5,W5,Y5) -> 4.2971821e+10 | AB5: 1.7365386e+10 | AC5: =AA5/305 -> 1.4089122e+08 | AD5: =AB5/305 -> 56935691
A6: 5 | B6: Bauchi | C6: 2.9222762e+09 | D6: 3.8254859e+09 | E6: 2.5440579e+09 | F6: 3.4472677e+09 | G6: 2.8645372e+09 | H6: 3.767747e+09 | I6: 2.5200156e+09 | J6: 3.4232254e+09 | K6: 2.875175e+09 | L6: 3.7783848e+09 | M6: 4.4538002e+09 | N6: 5.3570099e+09 | O6: 2.952271e+09 | P6: 3.833199e+09 | Q6: 4.3490488e+09 | R6: 5.2299767e+09 | S6: 3.7997968e+09 | T6: 4.5211688e+09 | U6: 3.6177337e+09 | V6: 4.3391057e+09 | W6: 4.1862017e+09 | X6: 4.9075737e+09 | Y6: 4.5248855e+09 | Z6: 5.2462575e+09 | AA6: =SUM(C6,E6,G6,I6,K6,M6,O6,Q6,S6,U6,W6,Y6) -> 4.16098e+10 | AB6: 4.3694115e+09 | AC6: =AA6/305 -> 1.3642557e+08 | AD6: =AB6/305 -> 14325939
A7: 6 | B7: Bayelsa | C7: 7.982833e+09 | D7: 9.3858044e+09 | E7: 8.3450247e+09 | F7: 9.8912517e+09 | G7: 8.8737927e+09 | H7: 1.0421916e+10 | I7: 7.3293024e+09 | J7: 8.8774259e+09 | K7: 7.4139461e+09 | L7: 8.9620696e+09 | M7: 8.9773387e+09 | N7: 1.0525462e+10 | O7: 8.228047e+09 | P7: 9.9371852e+09 | Q7: 1.0887663e+10 | R7: 1.2608667e+10 | S7: 1.009405e+10 | T7: 1.1735597e+10 | U7: 9.939723e+09 | V7: 1.158127e+10 | W7: 1.0541675e+10 | X7: 1.2183222e+10 | Y7: 1.2602484e+10 | Z7: 1.4244031e+10 | AA7: =SUM(C7,E7,G7,I7,K7,M7,O7,Q7,S7,U7,W7,Y7) -> 1.1121588e+11 | AB7: 1.2523812e+10 | AC7: =AA7/305 -> 3.6464223e+08 | AD7: =AB7/305 -> 41061680
A8: 7 | B8: Benue | C8: 2.9717139e+09 | D8: 3.5770518e+09 | E8: 2.6491331e+09 | F8: 3.254471e+09 | G8: 2.9551055e+09 | H8: 3.5604434e+09 | I8: 2.6179721e+09 | J8: 3.22331e+09 | K8: 2.9697369e+09 | L8: 3.5750747e+09 | M8: 4.4444216e+09 | N8: 5.0497595e+09 | O8: 3.0419923e+09 | P8: 3.6223134e+09 | Q8: 4.2817016e+09 | R8: 4.8812299e+09 | S8: 3.7149855e+09 | T8: 4.2631761e+09 | U8: 3.5379142e+09 | V8: 4.0861048e+09 | W8: 4.0723331e+09 | X8: 4.6205236e+09 | Y8: 4.392008e+09 | Z8: 4.9401986e+09 | AA8: =SUM(C8,E8,G8,I8,K8,M8,O8,Q8,S8,U8,W8,Y8) -> 4.1649018e+10 | AB8: 1.2399415e+10 | AC8: =AA8/305 -> 1.3655416e+08 | AD8: =AB8/305 -> 40653818
A9: 8 | B9: Borno | C9: 3.5473537e+09 | D9: 3.8903253e+09 | E9: 3.157998e+09 | F9: 3.5009696e+09 | G9: 3.4974526e+09 | H9: 3.8404242e+09 | I9: 3.1115996e+09 | J9: 3.4545713e+09 | K9: 3.511155e+09 | L9: 3.8541267e+09 | M9: 5.144254e+09 | N9: 5.4872257e+09 | O9: 3.5646978e+09 | P9: 3.9051807e+09 | Q9: 4.9504797e+09 | R9: 5.2909626e+09 | S9: 4.2745898e+09 | T9: 4.6150727e+09 | U9: 4.0709823e+09 | V9: 4.4114652e+09 | W9: 4.6700701e+09 | X9: 5.010553e+09 | Y9: 5.0166765e+09 | Z9: 5.3571594e+09 | AA9: =SUM(C9,E9,G9,I9,K9,M9,O9,Q9,S9,U9,W9,Y9) -> 4.8517309e+10 | AB9: 4.983331e+09 | AC9: =AA9/305 -> 1.5907314e+08 | AD9: =AB9/305 -> 16338790
A10: 9 | B10: Cross River | C10: 1.6734587e+09 | D10: 3.2282562e+09 | E10: 1.338234e+09 | F10: 2.8931225e+09 | G10: 1.6393807e+09 | H10: 3.1942237e+09 | I10: 1.3114577e+09 | J10: 2.8663007e+09 | K10: 1.628361e+09 | L10: 3.183204e+09 | M10: 2.9876533e+09 | N10: 4.5117382e+09 | O10: 1.7156577e+09 | P10: 3.2464495e+09 | Q10: 2.8478792e+09 | R10: 4.378671e+09 | S10: 2.2986566e+09 | T10: 3.8294484e+09 | U10: 2.131533e+09 | V10: 3.6623248e+09 | W10: 2.6078497e+09 | X10: 4.1386415e+09 | Y10: 2.8729862e+09 | Z10: 4.403778e+09 | AA10: =SUM(C10,E10,G10,I10,K10,M10,O10,Q10,S10,U10,W10,Y10) -> 2.5053108e+10 | AB10: 1.8104562e+10 | AC10: =AA10/305 -> 82141337 | AD10: =AB10/305 -> 59359220
A11: 10 | B11: Delta | C11: 7.46222e+09 | D11: 9.725687e+09 | E11: 7.9096994e+09 | F11: 1.0328901e+10 | G11: 7.384019e+09 | H11: 9.8032206e+09 | I11: 6.2396157e+09 | J11: 8.6588173e+09 | K11: 6.4898129e+09 | L11: 8.9090145e+09 | M11: 8.2588568e+09 | N11: 1.0678058e+10 | O11: 8.0515343e+09 | P11: 1.0505674e+10 | Q11: 1.42266e+10 | R11: 1.6525005e+10 | S11: 1.2811119e+10 | T11: 1.5109524e+10 | U11: 1.2098182e+10 | V11: 1.4396587e+10 | W11: 1.4099559e+10 | X11: 1.6397964e+10 | Y11: 1.6298138e+10 | Z11: 1.8596543e+10 | AA11: =SUM(C11,E11,G11,I11,K11,M11,O11,Q11,S11,U11,W11,Y11) -> 1.2132936e+11 | AB11: 5.1888005e+10 | AC11: =AA11/305 -> 3.9780116e+08 | AD11: =AB11/305 -> 1.7012461e+08
A12: 11 | B12: Ebonyi | C12: 2.7281957e+09 | D12: 2.8875029e+09 | E12: 2.457858e+09 | F12: 2.6152972e+09 | G12: 2.6948658e+09 | H12: 2.8545697e+09 | I12: 2.423282e+09 | J12: 2.5815423e+09 | K12: 2.7494611e+09 | L12: 2.9105023e+09 | M12: 3.8910672e+09 | N12: 4.067331e+09 | O12: 2.7575938e+09 | P12: 2.9211353e+09 | Q12: 3.7583335e+09 | R12: 3.9313472e+09 | S12: 3.2910271e+09 | T12: 3.4417768e+09 | U12: 2.9810655e+09 | V12: 3.3098184e+09 | W12: 3.3845809e+09 | X12: 3.7199637e+09 | Y12: 3.6343372e+09 | Z12: 3.970278e+09 | AA12: =SUM(C12,E12,G12,I12,K12,M12,O12,Q12,S12,U12,W12,Y12) -> 3.6751668e+10 | AB12: 5.1029024e+09 | AC12: =AA12/305 -> 1.2049727e+08 | AD12: =AB12/305 -> 16730827
A13: 12 | B13: Edo | C13: 2.3446538e+09 | D13: 3.3330854e+09 | E13: 2.0361924e+09 | F13: 3.0355232e+09 | G13: 2.5072094e+09 | H13: 3.5065402e+09 | I13: 2.0465635e+09 | J13: 3.0458943e+09 | K13: 2.3717292e+09 | L13: 3.37106e+09 | M13: 3.6584188e+09 | N13: 4.6577497e+09 | O13: 2.7379821e+09 | P13: 3.7263263e+09 | Q13: 4.5021404e+09 | R13: 5.4795854e+09 | S13: 3.9582906e+09 | T13: 4.9357356e+09 | U13: 3.9711974e+09 | V13: 4.9486424e+09 | W13: 4.5944641e+09 | X13: 5.5719091e+09 | Y13: 5.083147e+09 | Z13: 6.0605921e+09 | AA13: =SUM(C13,E13,G13,I13,K13,M13,O13,Q13,S13,U13,W13,Y13) -> 3.9811989e+10 | AB13: 2.5342829e+10 | AC13: =AA13/305 -> 1.3053111e+08 | AD13: =AB13/305 -> 83091243
... A37: 36 | B37: Zamfara | C37: 2.1801507e+09 | D37: 3.2086684e+09 | E37: 1.8685803e+09 | F37: 2.897098e+09 | G37: 2.137195e+09 | H37: 3.1657126e+09 | I37: 1.8423842e+09 | J37: 2.8709019e+09 | K37: 2.1604613e+09 | L37: 3.188979e+09 | M37: 3.4559626e+09 | N37: 4.4844802e+09 | O37: 2.197631e+09 | P37: 3.2252424e+09 | Q37: 3.0533307e+09 | R37: 4.3432966e+09 | S37: 2.5066656e+09 | T37: 3.7966315e+09 | U37: 2.356277e+09 | V37: 3.6462429e+09 | W37: 2.8311978e+09 | X37: 4.1211637e+09 | Y37: 3.1084926e+09 | Z37: 4.3984585e+09 | AA37: =SUM(C37,E37,G37,I37,K37,M37,O37,Q37,S37,U37,W37,Y37) -> 2.9698329e+10 | AB37: 6.0239949e+09 | AC37: =AA37/305 -> 97371569 | AD37: =AB37/305 -> 19750803
A38: 37 | B38: FCT | C38: 4.2710483e+09 | E38: 3.8604229e+09 | G38: 4.2111376e+09 | I38: 3.6512318e+09 | K38: 4.1133737e+09 | M38: 5.9605477e+09 | O38: 4.1829446e+09 | Q38: 5.7448598e+09 | S38: 4.9848448e+09 | U38: 4.7313756e+09 | W38: 5449486299 | Y38: 5.833037e+09 | AA38: =SUM(C38,E38,G38,I38,K38,M38,O38,Q38,S38,U38,W38,Y38) -> 5.699431e+10 | AC38: =AA38/305 -> 1.8686659e+08 | AD38: =AB38/305 -> 0
AA39: =SUM(AA2:AA38) -> 1.8817079e+12 | AC39: =AA39/305 -> 6.1695339e+09

Sheet 2018
A1: S/N | B1: State | C1: January (Net) | D1: January (Gross) | E1: February (Net) | F1: February (Gross) | G1: March (Net) | H1: March (Gross) | I1: April (Net) | J1: April (Gross) | K1: May (Net) | L1: May (Gross) | M1: June (Net) | N1: June (Gross) | O1: July (Net) | P1: July (Gross) | Q1: August (Net) | R1: August (Gross) | S1: September (Net) | T1: September (Gross) | U1: October (Net) | V1: October (Gross) | W1: November (Net) | X1: November (Gross) | Y1: December (Net) | Z1: December (Gross) | AA1: Total Net | AB1: Total IGR | AC1: Total Net USD | AD1: Total IGR USD
A2: 1 | B2: Abia | C2: 4.3244289e+09 | D2: 4.7946117e+09 | E2: 4.4100413e+09 | F2: 4.8802247e+09 | G2: 4.3047773e+09 | H2: 4.7749607e+09 | I2: 4.5469018e+09 | J2: 5.0170852e+09 | K2: 4.5117946e+09 | L2: 4.981978e+09 | M2: 4.7089121e+09 | N2: 5.1790955e+09 | O2: 4.6022776e+09 | P2: 5.0728466e+09 | Q2: 4.8496364e+09 | R2: 5.3202053e+09 | S2: 4.73012e+09 | T2: 5.200689e+09 | U2: 4.8649213e+09 | V2: 5.3354903e+09 | W2: 5.1137347e+09 | Y2: 4.2975595e+09 | Z2: 4.7681285e+09 | AA2: =SUM(C2,E2,G2,I2,K2,M2,O2,Q2,S2,U2,W2,Y2) -> 5.5265105e+10 | AB2: 1.4834904e+10 | AC2: =AA2/306 -> 1.8060492e+08 | AD2: =AB2/306 -> 48480080
A3: 2 | B3: Adamawa | C3: 3.8561912e+09 | D3: 4.3124125e+09 | E3: 3.9060668e+09 | F3: 4.3622881e+09 | G3: 3.7684394e+09 | H3: 4.2641496e+09 | I3: 4.0859055e+09 | J3: 4.5816157e+09 | K3: 4.0386701e+09 | L3: 4.5343803e+09 | M3: 4.4131659e+09 | N3: 4.9088761e+09 | O3: 4.1329991e+09 | P3: 4.6467702e+09 | Q3: 4.3134731e+09 | R3: 4.8272442e+09 | S3: 4.1401999e+09 | T3: 4.653971e+09 | U3: 4.188272e+09 | V3: 4.8620431e+09 | W3: 4.6067796e+09 | Y3: 3.9042035e+09 | Z3: 4.4179746e+09 | AA3: =SUM(C3,E3,G3,I3,K3,M3,O3,Q3,S3,U3,W3,Y3) -> 4.9354366e+10 | AB3: 6.2048767e+09 | AC3: =AA3/306 -> 1.6128878e+08 | AD3: =AB3/306 -> 20277375
A4: 3 | B4: Akwa Ibom | C4: 1.633957e+10 | D4: 1.7440735e+10 | E4: 1.7981943e+10 | F4: 1.9210307e+10 | G4: 1.7216171e+10 | H4: 1.8444535e+10 | I4: 1.5241957e+10 | J4: 1.6406721e+10 | K4: 1.686256e+10 | L4: 1.8027325e+10 | M4: 1.4013276e+10 | N4: 1.517804e+10 | O4: 1.5646012e+10 | P4: 1.6797826e+10 | Q4: 1.7115551e+10 | R4: 1.8267365e+10 | S4: 1.9437251e+10 | T4: 2.0589065e+10 | U4: 1.8462447e+10 | V4: 1.9614261e+10 | W4: 1.7489398e+10 | Y4: 1.4456958e+10 | Z4: 1.5620022e+10 | AA4: =SUM(C4,E4,G4,I4,K4,M4,O4,Q4,S4,U4,W4,Y4) -> 2.0026309e+11 | AB4: 2.421081e+10 | AC4: =AA4/306 -> 6.5445455e+08 | AD4: =AB4/306 -> 79120294
A5: 4 | B5: Anambra | C5: 4.3398009e+09 | D5: 4.467282e+09 | E5: 4.378983e+09 | F5: 4.5064642e+09 | G5: 4.2573104e+09 | H5: 4.3847915e+09 | I5: 4.5566511e+09 | J5: 4.6841322e+09 | K5: 4.5186293e+09 | L5: 4.6461104e+09 | M5: 4.8581891e+09 | N5: 4.9856702e+09 | O5: 4.6017431e+09 | P5: 4.7385598e+09 | Q5: 4.8206512e+09 | R5: 4.9574679e+09 | S5: 4.603945e+09 | T5: 4.7407617e+09 | U5: 4.8318853e+09 | V5: 4.968702e+09 | W5: 5.1103381e+09 | Y5: 4.4144999e+09 | Z5: 4.5513166e+09 | AA5: =SUM(C5,E5,G5,I5,K5,M5,O5,Q5,S5,U5,W5,Y5) -> 5.5292626e+10 | AB5: 1.9305268e+10 | AC5: =AA5/306 -> 1.8069486e+08 | AD5: =AB5/306 -> 63089110
A6: 5 | B6: Bauchi | C6: 4.2960209e+09 | D6: 5.1142316e+09 | E6: 4.2194652e+09 | F6: 5.165487e+09 | G6: 4.2101852e+09 | H6: 5.0691148e+09 | I6: 4.2687035e+09 | J6: 5.4408762e+09 | K6: 4.0766102e+09 | L6: 5.3819563e+09 | M6: 4.9886738e+09 | N6: 5.8476034e+09 | O6: 4.1906991e+09 | P6: 5.5132001e+09 | Q6: 4.3993181e+09 | R6: 5.7218191e+09 | S6: 4.6601978e+09 | T6: 5.5362824e+09 | U6: 4.8948003e+09 | V6: 5.7708849e+09 | W6: 5.29129e+09 | Y6: 4.4703784e+09 | Z6: 5.2578217e+09 | AA6: =SUM(C6,E6,G6,I6,K6,M6,O6,Q6,S6,U6,W6,Y6) -> 5.3966343e+10 | AB6: 9.6908322e+09 | AC6: =AA6/306 -> 1.763606e+08 | AD6: =AB6/306 -> 31669386
A7: 6 | B7: Bayelsa | C7: 1.2629316e+10 | D7: 1.4272437e+10 | E7: 1.3666642e+10 | F7: 1.5309762e+10 | G7: 1.32197e+10 | H7: 1.486282e+10 | I7: 1.2351885e+10 | J7: 1.3995005e+10 | K7: 1.2665267e+10 | L7: 1.4308387e+10 | M7: 1.1015988e+10 | N7: 1.2659108e+10 | O7: 1.1997706e+10 | P7: 1.3612232e+10 | Q7: 1.2753584e+10 | R7: 1.4368109e+10 | S7: 1.2998259e+10 | T7: 1.4612784e+10 | U7: 1.3585327e+10 | V7: 1.5199853e+10 | W7: 1.3618709e+10 | Y7: 1.0729801e+10 | Z7: 1.2277661e+10 | AA7: =SUM(C7,E7,G7,I7,K7,M7,O7,Q7,S7,U7,W7,Y7) -> 1.5123218e+11 | AB7: 1.3636546e+10 | AC7: =AA7/306 -> 4.9422282e+08 | AD7: =AB7/306 -> 44563875
A8: 7 | B8: Benue | C8: 4.2776795e+09 | D8: 4.8265775e+09 | E8: 4.3148009e+09 | F8: 4.8636989e+09 | G8: 4.2231559e+09 | H8: 4.7720538e+09 | I8: 4.5611359e+09 | J8: 5.1100339e+09 | K8: 4.5374254e+09 | L8: 5.0863233e+09 | M8: 4.9386432e+09 | N8: 5.4875412e+09 | O8: 4.6397037e+09 | P8: 5.1939921e+09 | Q8: 4.8450584e+09 | R8: 5.3993468e+09 | S8: 4.6570874e+09 | T8: 5.2113758e+09 | U8: 4.8846513e+09 | V8: 5.4389397e+09 | W8: 5.1697287e+09 | Y8: 4.4054157e+09 | Z8: 4.9597041e+09 | AA8: =SUM(C8,E8,G8,I8,K8,M8,O8,Q8,S8,U8,W8,Y8) -> 5.5454486e+10 | AB8: 1.1215483e+10 | AC8: =AA8/306 -> 1.8122381e+08 | AD8: =AB8/306 -> 36651904
A9: 8 | B9: Borno | C9: 4.8737895e+09 | D9: 5.213249e+09 | E9: 4.9322587e+09 | F9: 5.2717182e+09 | G9: 4.8409833e+09 | H9: 5.1804427e+09 | I9: 5.2126098e+09 | J9: 5.5520693e+09 | K9: 5.1597346e+09 | L9: 5.4991941e+09 | M9: 5.6311922e+09 | N9: 5.9706516e+09 | O9: 5.3042536e+09 | P9: 5.6451419e+09 | Q9: 5.503847e+09 | R9: 5.8447353e+09 | S9: 5.3326968e+09 | T9: 5.6735851e+09 | U9: 5.5751269e+09 | V9: 5.9160152e+09 | W9: 5.8885341e+09 | Y9: 5.0313963e+09 | Z9: 5.3722845e+09 | AA9: =SUM(C9,E9,G9,I9,K9,M9,O9,Q9,S9,U9,W9,Y9) -> 6.3286423e+10 | AB9: 6.5243009e+09 | AC9: =AA9/306 -> 2.0681837e+08 | AD9: =AB9/306 -> 21321245
A10: 9 | B10: Cross River | C10: 2.7512448e+09 | D10: 4.3127181e+09 | E10: 2.7901595e+09 | F10: 4.3516333e+09 | G10: 2.7285347e+09 | H10: 4.2900086e+09 | I10: 3.0165065e+09 | J10: 4.5779804e+09 | K10: 2.9667728e+09 | L10: 4.5282467e+09 | M10: 3.3645139e+09 | N10: 4.9259878e+09 | O10: 3.1345295e+09 | P10: 4.6474421e+09 | Q10: 3.3116287e+09 | R10: 4.8245413e+09 | S10: 3.1522065e+09 | T10: 4.6651191e+09 | U10: 3.2982702e+09 | V10: 4.8751565e+09 | W10: 3.5673335e+09 | Y10: 2.9086938e+09 | Z10: 4.4216064e+09 | AA10: =SUM(C10,E10,G10,I10,K10,M10,O10,Q10,S10,U10,W10,Y10) -> 3.6990394e+10 | AB10: 1.7552113e+10 | AC10: =AA10/306 -> 1.2088364e+08 | AD10: =AB10/306 -> 57359846
A11: 10 | B11: Delta | C11: 1.5970921e+10 | D11: 1.8272643e+10 | E11: 1.7167312e+10 | F11: 1.946901e+10 | G11: 1.739939e+10 | H11: 1.9701088e+10 | I11: 1.7015899e+10 | J11: 1.9317597e+10 | K11: 1.7333534e+10 | L11: 1.9635231e+10 | M11: 1.5104273e+10 | N11: 1.740597e+10 | O11: 1.6456222e+10 | P11: 1.8728658e+10 | Q11: 1.7843532e+10 | R11: 2.0115969e+10 | S11: 2.0910697e+10 | T11: 2.2084226e+10 | U11: 2.0976071e+10 | V11: 2.21496e+10 | W11: 2.1158204e+10 | Y11: 1.7360641e+10 | Z11: 1.853417e+10 | AA11: =SUM(C11,E11,G11,I11,K11,M11,O11,Q11,S11,U11,W11,Y11) -> 2.146967e+11 | AB11: 5.8439599e+10 | AC11: =AA11/306 -> 7.0162319e+08 | AD11: =AB11/306 -> 1.9097908e+08
A12: 11 | B12: Ebonyi | C12: 3.5312571e+09 | D12: 3.86967e+09 | E12: 3.5754538e+09 | F12: 3.9148499e+09 | G12: 3.5261337e+09 | H12: 3.8613187e+09 | I12: 3.7664487e+09 | J12: 4.1080864e+09 | K12: 3.5723538e+09 | L12: 4.0731815e+09 | M12: 3.9087985e+09 | N12: 4.4109322e+09 | O12: 3.6882228e+09 | P12: 4.1953292e+09 | Q12: 3.8855319e+09 | R12: 4.3932444e+09 | S12: 3.6764725e+09 | T12: 4.1828043e+09 | U12: 3.9746771e+09 | V12: 4.4034808e+09 | W12: 4.2153224e+09 | Y12: 3.6001727e+09 | Z12: 4.0254829e+09 | AA12: =SUM(C12,E12,G12,I12,K12,M12,O12,Q12,S12,U12,W12,Y12) -> 4.4920845e+10 | AB12: 6.1445871e+09 | AC12: =AA12/306 -> 1.4680015e+08 | AD12: =AB12/306 -> 20080350
A13: 12 | B13: Edo | C13: 5.4927621e+09 | D13: 5.9518863e+09 | E13: 5.2967614e+09 | F13: 6.2758855e+09 | G13: 5.7663067e+09 | H13: 6.2254308e+09 | I13: 5.6280747e+09 | J13: 6.0871989e+09 | K13: 5.6157845e+09 | L13: 6.0749086e+09 | M13: 5.9126732e+09 | N13: 6.3717974e+09 | O13: 5.6368991e+09 | P13: 6.1095352e+09 | Q13: 6.1096141e+09 | R13: 6.5822503e+09 | S13: 5.9369324e+09 | T13: 6.4095685e+09 | U13: 6.2848371e+09 | V13: 6.7574732e+09 | W13: 6.4058544e+09 | Y13: 5.3857972e+09 | Z13: 5.8584333e+09 | AA13: =SUM(C13,E13,G13,I13,K13,M13,O13,Q13,S13,U13,W13,Y13) -> 6.9472297e+10 | AB13: 2.8425497e+10 | AC13: =AA13/306 -> 2.2703365e+08 | AD13: =AB13/306 -> 92893781
... A37: 36 | B37: Zamfara | C37: 3.0109737e+09 | D37: 4.3021144e+09 | E37: 3.0535558e+09 | F37: 4.3446966e+09 | G37: 2.9698242e+09 | H37: 4.2609649e+09 | I37: 3.2664486e+09 | J37: 4.5575893e+09 | K37: 3.2340588e+09 | L37: 4.5251995e+09 | M37: 3.6030736e+09 | N37: 4.8942143e+09 | O37: 3.3228827e+09 | P37: 4.6202531e+09 | Q37: 3.7804051e+09 | R37: 4.8154211e+09 | S37: 3.6039743e+09 | T37: 4.6389903e+09 | U37: 3.8132128e+09 | V37: 4.8482287e+09 | W37: 4.064923e+09 | Y37: 3.3829244e+09 | Z37: 4.4179403e+09 | AA37: =SUM(C37,E37,G37,I37,K37,M37,O37,Q37,S37,U37,W37,Y37) -> 4.1106257e+10 | AB37: 8.2066956e+09 | AC37: =AA37/306 -> 1.3433417e+08 | AD37: =AB37/306 -> 26819267
A38: 37 | B38: FCT | C38: 5.6247926e+09 | E38: 5.7181791e+09 | G38: 5.6305087e+09 | I38: 6.0467314e+09 | K38: 5.9621833e+09 | M38: 6.5290636e+09 | O38: 6.1713347e+09 | Q38: 6.2802262e+09 | S38: 6.2015261e+09 | U38: 6.376361e+09 | W38: 6.7959861e+09 | Y38: 5.8204204e+09 | AA38: =SUM(C38,E38,G38,I38,K38,M38,O38,Q38,S38,U38,W38,Y38) -> 7.3157313e+10 | AB38: 6.5519664e+10 | AC38: =AA38/306 -> 2.3907619e+08 | AD38: =AB38/306 -> 2.1411655e+08
AA39: =SUM(AA2:AA38) -> 2.5657221e+12 | AC39: =AA39/306 -> 8.3847129e+09

Sheet 2019
A1: S/N | B1: State | C1: January (Net) | D1: January (Gross) | E1: February (Net) | F1: February (Gross) | G1: March (Net) | H1: March (Gross) | I1: April (Net) | J1: April (Gross) | K1: May (Net) | L1: May (Gross) | M1: June (Net) | N1: June (Gross) | O1: July (Net) | P1: July (Gross) | Q1: August (Net) | R1: August (Gross) | S1: September (Net) | T1: September (Gross) | U1: October (Net) | V1: October (Gross) | W1: November (Net) | X1: November (Gross) | Y1: December (Net) | Z1: December (Gross) | AA1: Total Net | AB1: Total IGR | AC1: Total Net USD | AD1: Total IGR USD
A2: 1 | B2: Abia | C2: 4.4499763e+09 | D2: 4.9205452e+09 | E2: 4.1733125e+09 | F2: 4.6453348e+09 | G2: 4.1490771e+09 | H2: 4.6210995e+09 | I2: 4.0956167e+09 | J2: 4.567639e+09 | K2: 4.4440746e+09 | L2: 4.9160969e+09 | M2: 4.822019e+09 | N2: 5.2679245e+09 | O2: 4.5701962e+09 | P2: 5.1955024e+09 | Q2: 4.3507475e+09 | R2: 5.2082822e+09 | S2: 4.2578407e+09 | T2: 5.0427009e+09 | U2: 4.3809802e+09 | V2: 5.1658403e+09 | W2: 4.0484682e+09 | X2: 4.8333283e+09 | Y2: 4.3325963e+09 | Z2: 5.1174565e+09 | AA2: =SUM(C2,E2,G2,I2,K2,M2,O2,Q2,S2,U2,W2,Y2) -> 5.2074905e+10 | AB2: 1.5499929e+10 | AC2: =AA2/306 -> 1.7017943e+08 | AD2: =AB2/306 -> 50653364
A3: 2 | B3: Adamawa | C3: 4.0271341e+09 | D3: 4.5409053e+09 | E3: 3.7368511e+09 | F3: 4.2371611e+09 | G3: 3.6926833e+09 | H3: 4.1929933e+09 | I3: 3.6996729e+09 | J3: 4.1802384e+09 | K3: 4.2006638e+09 | L3: 4.6614848e+09 | M3: 4.5596885e+09 | N3: 5.0205096e+09 | O3: 4.3119275e+09 | P3: 4.7727485e+09 | Q3: 4.1664704e+09 | R3: 4.8613198e+09 | S3: 4.0605205e+09 | T3: 4.6826953e+09 | U3: 4.1890041e+09 | V3: 4.8111789e+09 | W3: 3.7898823e+09 | X3: 4.4120571e+09 | Y3: 4.1373919e+09 | Z3: 4.7595667e+09 | AA3: =SUM(C3,E3,G3,I3,K3,M3,O3,Q3,S3,U3,W3,Y3) -> 4.857189e+10 | AB3: 9.7046502e+09 | AC3: =AA3/306 -> 1.5873167e+08 | AD3: =AB3/306 -> 31714543
A4: 3 | B4: Akwa Ibom | C4: 1.4513722e+10 | D4: 1.5676786e+10 | E4: 1.5319798e+10 | F4: 1.638692e+10 | G4: 1.4750828e+10 | H4: 1.581795e+10 | I4: 1.4060496e+10 | J4: 1.5127618e+10 | K4: 1.320756e+10 | L4: 1.4274682e+10 | M4: 1.2997646e+10 | N4: 1.4064768e+10 | O4: 1.491283e+10 | P4: 1.5979953e+10 | Q4: 1.4061109e+10 | R4: 1.5388683e+10 | S4: 1.4875462e+10 | T4: 1.6130361e+10 | U4: 1.4046324e+10 | V4: 1.5327301e+10 | W4: 1.4772806e+10 | X4: 1.6053783e+10 | Y4: 1.5112298e+10 | Z4: 1.6393275e+10 | AA4: =SUM(C4,E4,G4,I4,K4,M4,O4,Q4,S4,U4,W4,Y4) -> 1.7263088e+11 | AB4: 35504936358 | AC4: =AA4/306 -> 5.641532e+08 | AD4: =AB4/306 -> 1.160292e+08
A5: 4 | B5: Anambra | C5: 4.5159133e+09 | D5: 4.65273e+09 | E5: 4.2265915e+09 | F5: 4.3714706e+09 | G5: 4.1768336e+09 | H5: 4.3217128e+09 | I5: 4.1456544e+09 | J5: 4.2905335e+09 | K5: 4.6837383e+09 | L5: 4.8286174e+09 | M5: 5.0098863e+09 | N5: 5.1547654e+09 | O5: 4.753529e+09 | P5: 4.8984081e+09 | Q5: 4.6222265e+09 | R5: 4.9862382e+09 | S5: 4.4811445e+09 | T5: 4.7724816e+09 | U5: 4.6227098e+09 | V5: 4.9140468e+09 | W5: 4.2411352e+09 | X5: 4.5324722e+09 | Y5: 4.5991447e+09 | Z5: 4.8904818e+09 | AA5: =SUM(C5,E5,G5,I5,K5,M5,O5,Q5,S5,U5,W5,Y5) -> 5.4078507e+10 | AB5: 2.6369196e+10 | AC5: =AA5/306 -> 1.7672715e+08 | AD5: =AB5/306 -> 86173843
A6: 5 | B6: Bauchi | C6: 4.5920331e+09 | D6: 5.3794764e+09 | E6: 4.1842999e+09 | F6: 5.0259557e+09 | G6: 3.9001469e+09 | H6: 4.9770095e+09 | I6: 3.8936844e+09 | J6: 4.9705471e+09 | K6: 4.4681708e+09 | L6: 5.5450335e+09 | M6: 4.8775365e+09 | N6: 5.9543992e+09 | O6: 4.5951904e+09 | P6: 5.6720531e+09 | Q6: 4.599018e+09 | R6: 5.8920441e+09 | S6: 4.3168985e+09 | T6: 5.5587825e+09 | U6: 4.4671591e+09 | V6: 5.7090432e+09 | W6: 3.9926082e+09 | X6: 5.2344923e+09 | Y6: 4.4029322e+09 | Z6: 5.6448163e+09 | AA6: =SUM(C6,E6,G6,I6,K6,M6,O6,Q6,S6,U6,W6,Y6) -> 5.2289678e+10 | AB6: 1.2293319e+10 | AC6: =AA6/306 -> 1.708813e+08 | AD6: =AB6/306 -> 40174245
A7: 6 | B7: Bayelsa | C7: 1.1614714e+10 | D7: 1.3162574e+10 | E7: 1.1635573e+10 | F7: 1.3182344e+10 | G7: 1.1144225e+10 | H7: 1.2690997e+10 | I7: 1.0392154e+10 | J7: 1.1938926e+10 | K7: 1.0238317e+10 | L7: 1.1785088e+10 | M7: 1.0464117e+10 | N7: 1.1589342e+10 | O7: 1.3401556e+10 | P7: 1.4526781e+10 | Q7: 1.2813309e+10 | R7: 1.4167618e+10 | S7: 1.3066338e+10 | T7: 1.4614639e+10 | U7: 1.2391705e+10 | V7: 1.3940005e+10 | W7: 1.2237554e+10 | X7: 1.3706397e+10 | Y7: 1.2665731e+10 | Z7: 1.4134574e+10 | AA7: =SUM(C7,E7,G7,I7,K7,M7,O7,Q7,S7,U7,W7,Y7) -> 1.4206529e+11 | AB7: 16342762532 | AC7: =AA7/306 -> 4.6426566e+08 | AD7: =AB7/306 -> 53407721
A8: 7 | B8: Benue | C8: 4.5162263e+09 | D8: 5.0705147e+09 | E8: 4.1763223e+09 | F8: 4.7291191e+09 | G8: 4.1437679e+09 | H8: 4.6965648e+09 | I8: 4.1282489e+09 | J8: 4.6810458e+09 | K8: 4.6726136e+09 | L8: 5.2254105e+09 | M8: 5.0687724e+09 | N8: 5.6215692e+09 | O8: 4.8677708e+09 | P8: 5.3625073e+09 | Q8: 4.7356935e+09 | R8: 5.4561232e+09 | S8: 4.5935308e+09 | T8: 5.2412859e+09 | U8: 4.7440966e+09 | V8: 5.3918517e+09 | W8: 4.2878379e+09 | X8: 4.935593e+09 | Y8: 4.6866896e+09 | Z8: 5.3344447e+09 | AA8: =SUM(C8,E8,G8,I8,K8,M8,O8,Q8,S8,U8,W8,Y8) -> 5.4621571e+10 | AB8: 1.7179638e+10 | AC8: =AA8/306 -> 1.7850186e+08 | AD8: =AB8/306 -> 56142608
A9: 8 | B9: Borno | C9: 5.1375732e+09 | D9: 5.4784615e+09 | E9: 4.7791338e+09 | F9: 5.1207069e+09 | G9: 4.7448971e+09 | H9: 5.0864702e+09 | I9: 4.7134949e+09 | J9: 5.055068e+09 | K9: 5.3072516e+09 | L9: 5.6488247e+09 | M9: 5.7437815e+09 | N9: 6.0853546e+09 | O9: 5.4692379e+09 | P9: 5.810811e+09 | Q9: 5.3814797e+09 | R9: 5.9467753e+09 | S9: 5.2020818e+09 | T9: 5.6947028e+09 | U9: 5.3396296e+09 | V9: 5.8322506e+09 | W9: 4.8635335e+09 | X9: 5.3561545e+09 | Y9: 5.2890044e+09 | Z9: 5.7816254e+09 | AA9: =SUM(C9,E9,G9,I9,K9,M9,O9,Q9,S9,U9,W9,Y9) -> 6.1971099e+10 | AB9: 8175248326 | AC9: =AA9/306 -> 2.0251993e+08 | AD9: =AB9/306 -> 26716498
A10: 9 | B10: Cross River | C10: 2.9443018e+09 | D10: 4.5211881e+09 | E10: 2.7175213e+09 | F10: 4.2383757e+09 | G10: 2.7348893e+09 | H10: 4.1872166e+09 | I10: 2.7216526e+09 | J10: 4.1739799e+09 | K10: 3.2097013e+09 | L10: 4.6620286e+09 | M10: 3.5600072e+09 | N10: 5.0123345e+09 | O10: 3.3304312e+09 | P10: 4.7827585e+09 | Q10: 3.1531262e+09 | R10: 4.8766435e+09 | S10: 3.0356516e+09 | T10: 4.6864944e+09 | U10: 3.2214827e+09 | V10: 4.8723255e+09 | W10: 2.7754202e+09 | X10: 4.426263e+09 | Y10: 3.0962107e+09 | Z10: 4.7470535e+09 | AA10: =SUM(C10,E10,G10,I10,K10,M10,O10,Q10,S10,U10,W10,Y10) -> 3.6500396e+10 | AB10: 2.2597064e+10 | AC10: =AA10/306 -> 1.1928234e+08 | AD10: =AB10/306 -> 73846614
A11: 10 | B11: Delta | C11: 1.8672329e+10 | D11: 1.9845858e+10 | E11: 1.9152148e+10 | F11: 2.0323309e+10 | G11: 1.931517e+10 | H11: 2.0486331e+10 | I11: 1.8271814e+10 | J11: 1.9442976e+10 | K11: 1.592532e+10 | L11: 1.7184901e+10 | M11: 1.6717018e+10 | N11: 1.79766e+10 | O11: 1.9847722e+10 | P11: 2.1107304e+10 | Q11: 1.8319598e+10 | R11: 1.980549e+10 | S11: 1.874264e+10 | T11: 2.0155858e+10 | U11: 1.8143769e+10 | V11: 1.9556987e+10 | W11: 1.8814725e+10 | X11: 2.0227942e+10 | Y11: 1.809097e+10 | Z11: 1.9504187e+10 | AA11: =SUM(C11,E11,G11,I11,K11,M11,O11,Q11,S11,U11,W11,Y11) -> 2.2001322e+11 | AB11: 6.4678797e+10 | AC11: =AA11/306 -> 7.1899746e+08 | AD11: =AB11/306 -> 2.1136862e+08
A12: 11 | B12: Ebonyi | C12: 3.6529605e+09 | D12: 4.075588e+09 | E12: 3.3952344e+09 | F12: 3.8158344e+09 | G12: 3.3839841e+09 | H12: 3.8030706e+09 | I12: 3.5123372e+09 | J12: 3.7563716e+09 | K12: 3.8330144e+09 | L12: 4.2050195e+09 | M12: 4.1987847e+09 | N12: 4.5115141e+09 | O12: 4.0065736e+09 | P12: 4.3184011e+09 | Q12: 3.8537778e+09 | R12: 4.3952209e+09 | S12: 3.7456268e+09 | T12: 4.2134704e+09 | U12: 3.8995146e+09 | V12: 4.3668961e+09 | W12: 3.545178e+09 | X12: 4.0070693e+09 | Y12: 3.8605375e+09 | Z12: 4.3273492e+09 | AA12: =SUM(C12,E12,G12,I12,K12,M12,O12,Q12,S12,U12,W12,Y12) -> 4.4887524e+10 | AB12: 9.8235239e+09 | AC12: =AA12/306 -> 1.4669125e+08 | AD12: =AB12/306 -> 32103019
A13: 12 | B13: Edo | C13: 5.5336305e+09 | D13: 6.1306919e+09 | E13: 5.3145706e+09 | F13: 5.9199885e+09 | G13: 5.1920023e+09 | H13: 5.7974202e+09 | I13: 5.1020011e+09 | J13: 5.707419e+09 | K13: 5.3369166e+09 | L13: 5.9423345e+09 | M13: 5.4791979e+09 | N13: 6.0846158e+09 | O13: 5.6381606e+09 | P13: 6.2435786e+09 | Q13: 5.6003076e+09 | R13: 6.4196755e+09 | S13: 5.4638563e+09 | T13: 6.2105496e+09 | U13: 5.5340682e+09 | V13: 6.2807615e+09 | W13: 5.0991813e+09 | X13: 5.8458746e+09 | Y13: 5.4555105e+09 | Z13: 6.2022038e+09 | AA13: =SUM(C13,E13,G13,I13,K13,M13,O13,Q13,S13,U13,W13,Y13) -> 6.4749403e+10 | AB13: 3.5227995e+10 | AC13: =AA13/306 -> 2.1159936e+08 | AD13: =AB13/306 -> 1.1512417e+08
... A37: 36 | B37: Zamfara | C37: 3.5018882e+09 | D37: 4.5369042e+09 | E37: 3.1808339e+09 | F37: 4.2144755e+09 | G37: 3.147828e+09 | H37: 4.1814696e+09 | I37: 3.1398455e+09 | J37: 4.1734871e+09 | K37: 3.6186478e+09 | L37: 4.6522894e+09 | M37: 3.9710534e+09 | N37: 5.004695e+09 | O37: 3.7275891e+09 | P37: 4.7612306e+09 | Q37: 3.5956625e+09 | R37: 4.8566453e+09 | S37: 3.4790306e+09 | T37: 4.6673389e+09 | U37: 3.7064873e+09 | V37: 4.7993964e+09 | W37: 3.3105081e+09 | X37: 4.4034172e+09 | Y37: 3.6484962e+09 | Z37: 4.7414053e+09 | AA37: =SUM(C37,E37,G37,I37,K37,M37,O37,Q37,S37,U37,W37,Y37) -> 4.2027871e+10 | AB37: 1.5416043e+10 | AC37: =AA37/306 -> 1.3734598e+08 | AD37: =AB37/306 -> 50379227
A38: 37 | B38: FCT | C38: 5.9048742e+09 | E38: 5.5183175e+09 | G38: 5.4908963e+09 | I38: 5.447537e+09 | K38: 6.0926842e+09 | M38: 6.5847669e+09 | O38: 6.3025245e+09 | Q38: 6.4707435e+09 | S38: 6.1777177e+09 | U38: 6.2971299e+09 | W38: 5.7976569e+09 | Y38: 6.1922203e+09 | AA38: =SUM(C38,E38,G38,I38,K38,M38,O38,Q38,S38,U38,W38,Y38) -> 7.2277069e+10 | AB38: 7.4564181e+10 | AC38: =AA38/306 -> 2.3619957e+08 | AD38: =AB38/306 -> 2.4367379e+08
AA39: =SUM(AA2:AA38) -> 2.4849086e+12 | AC39: =AA39/306 -> 8.1206163e+09

Sheet 2020
A1: S/N | B1: State | C1: January (Net) | D1: January (Gross) | E1: February (Net) | F1: February (Gross) | G1: March (Net) | H1: March (Gross) | I1: April (Net) | J1: April (Gross) | K1: May (Net) | L1: May (Gross) | M1: June (Net) | N1: June (Gross) | O1: July (Net) | P1: July (Gross) | Q1: August (Net) | R1: August (Gross) | S1: September (Net) | T1: September (Gross) | U1: October (Net) | V1: October (Gross) | W1: November (Net) | X1: November (Gross) | Y1: December (Net) | Z1: December (Gross) | AA1: Total Net | AB1: Total IGR | AC1: Total Net USD | AD1: Total IGR USD
A2: 1 | B2: Abia | C2: 3.9256216e+09 | D2: 4.7104817e+09 | E2: 3.5485185e+09 | F2: 4.31761e+09 | G2: 4.1761169e+09 | H2: 4.9452085e+09 | I2: 3.6291553e+09 | J2: 4.3982468e+09 | K2: 3.6286113e+09 | L2: 4.0283017e+09 | M2: 4.2131144e+09 | N2: 4.6367151e+09 | O2: 4.5681571e+09 | P2: 4.9917578e+09 | Q2: 4.4762208e+09 | R2: 4.9498611e+09 | S2: 4.2814845e+09 | T2: 4.7551249e+09 | U2: 3.7970525e+09 | V2: 4.2706928e+09 | W2: 3.7924149e+09 | X2: 4.2660552e+09 | Y2: 3.9251801e+09 | Z2: 4.3995972e+09 | AA2: =SUM(C2,E2,G2,I2,K2,M2,O2,Q2,S2,U2,W2,Y2) -> 4.7961648e+10 | AB2: 1.5921226e+10 | AC2: ='2020'!AA2/356 -> 1.3472373e+08 | AD2: =AB2/356 -> 44722545
A3: 2 | B3: Adamawa | C3: 3.8789306e+09 | D3: 4.4097359e+09 | E3: 3.3837312e+09 | F3: 3.9493758e+09 | G3: 3.9126619e+09 | H3: 4.4783064e+09 | I3: 3.5831789e+09 | J3: 4.1488234e+09 | K3: 3.5300165e+09 | L3: 3.7669422e+09 | M3: 4.3626777e+09 | N3: 4.5996034e+09 | O3: 4.4938749e+09 | P3: 4.7308006e+09 | Q3: 4.6271139e+09 | R3: 4.8671322e+09 | S3: 4.3211502e+09 | T3: 4.5611685e+09 | U3: 3.8510062e+09 | V3: 4.0910245e+09 | W3: 3.862155e+09 | X3: 4.1131715e+09 | Y3: 4.0704695e+09 | Z3: 4.3222628e+09 | AA3: =SUM(C3,E3,G3,I3,K3,M3,O3,Q3,S3,U3,W3,Y3) -> 4.7876966e+10 | AB3: 8.3298707e+09 | AC3: ='2020'!AA3/356 -> 1.3448586e+08 | AD3: =AB3/356 -> 23398513
A4: 3 | B4: Akwa Ibom | C4: 1.2966616e+10 | D4: 1.4247593e+10 | E4: 1.2530035e+10 | F4: 1.3808e+10 | G4: 1.5958621e+10 | H4: 1.7236586e+10 | I4: 1.1222671e+10 | J4: 1.2500636e+10 | K4: 1.1365257e+10 | L4: 1.2363979e+10 | M4: 9.8822212e+09 | N4: 1.0880943e+10 | O4: 1.3273121e+10 | P4: 1.4271843e+10 | Q4: 1.0334321e+10 | R4: 1.1348796e+10 | S4: 1.2316725e+10 | T4: 1.3331201e+10 | U4: 1.0824122e+10 | V4: 1.1838597e+10 | W4: 1.0479862e+10 | X4: 1.1494337e+10 | Y4: 1.0324664e+10 | Z4: 1.1276316e+10 | AA4: =SUM(C4,E4,G4,I4,K4,M4,O4,Q4,S4,U4,W4,Y4) -> 1.4147824e+11 | AB4: 3.069677e+10 | AC4: ='2020'!AA4/356 -> 3.9741078e+08 | AD4: =AB4/356 -> 86226883
A5: 4 | B5: Anambra | C5: 4.2041031e+09 | D5: 4.4954402e+09 | E5: 3.5315289e+09 | F5: 4.0463053e+09 | G5: 4.0867329e+09 | H5: 4.6015092e+09 | I5: 3.8472973e+09 | J5: 4.2550056e+09 | K5: 3.7070043e+09 | L5: 3.8721728e+09 | M5: 4.5235478e+09 | N5: 4.6887162e+09 | O5: 4.7339875e+09 | P5: 4.8991559e+09 | Q5: 4.8874422e+09 | R5: 5.0682647e+09 | S5: 4.5978573e+09 | T5: 4.7786798e+09 | U5: 4.0630079e+09 | V5: 4.2438304e+09 | W5: 4.1349114e+09 | X5: 4.3157339e+09 | Y5: 4.4331061e+09 | Z5: 4.6147054e+09 | AA5: =SUM(C5,E5,G5,I5,K5,M5,O5,Q5,S5,U5,W5,Y5) -> 5.0750527e+10 | AB5: 2.8009907e+10 | AC5: ='2020'!AA5/356 -> 1.4255766e+08 | AD5: =AB5/356 -> 78679513
A6: 5 | B6: Bauchi | C6: 3.9778853e+09 | D6: 5.2197693e+09 | E6: 3.4195408e+09 | F6: 4.6902807e+09 | G6: 4.056767e+09 | H6: 5.3275069e+09 | I6: 3.6971664e+09 | J6: 4.9679063e+09 | K6: 3.5180989e+09 | L6: 4.4688407e+09 | M6: 4.4881782e+09 | N6: 5.4389201e+09 | O6: 4.6332976e+09 | P6: 5.5840394e+09 | Q6: 4.7416214e+09 | R6: 5.7276165e+09 | S6: 4.4081129e+09 | T6: 5.394108e+09 | U6: 3.8726682e+09 | V6: 4.8371307e+09 | W6: 3.928081e+09 | X6: 4.8925435e+09 | Y6: 4.1152752e+09 | Z6: 5.0805145e+09 | AA6: =SUM(C6,E6,G6,I6,K6,M6,O6,Q6,S6,U6,W6,Y6) -> 4.8856693e+10 | AB6: 1.3039295e+10 | AC6: ='2020'!AA6/356 -> 1.372379e+08 | AD6: =AB6/356 -> 36627233
A7: 6 | B7: Bayelsa | C7: 1.178412e+10 | D7: 1.3391565e+10 | E7: 1.0689034e+10 | F7: 1.216292e+10 | G7: 1.2789802e+10 | H7: 1.4263688e+10 | I7: 9.3838009e+09 | J7: 1.0624354e+10 | K7: 8.9308305e+09 | L7: 9.9712606e+09 | M7: 8.849595e+09 | N7: 9.8566917e+09 | O7: 1.1186365e+10 | P7: 1.2193462e+10 | Q7: 8.3333615e+09 | R7: 1.0285863e+10 | S7: 8.2110044e+09 | T7: 1.0163506e+10 | U7: 6.7575414e+09 | V7: 8.7100428e+09 | W7: 6.8202788e+09 | X7: 8.7727802e+09 | Y7: 7.5103922e+09 | Z7: 9.4636704e+09 | AA7: =SUM(C7,E7,G7,I7,K7,M7,O7,Q7,S7,U7,W7,Y7) -> 1.1124613e+11 | AB7: 12180775143 | AC7: ='2020'!AA7/356 -> 3.1248912e+08 | AD7: =AB7/356 -> 34215661
A8: 7 | B8: Benue | C8: 3.2713373e+09 | D8: 4.9257683e+09 | E8: 3.2495207e+09 | F8: 4.4044245e+09 | G8: 3.8484044e+09 | H8: 5.0033082e+09 | I8: 3.5171866e+09 | J8: 4.6720904e+09 | K8: 3.4155672e+09 | L8: 4.2154385e+09 | M8: 4.3046548e+09 | N8: 5.1045261e+09 | O8: 4.4508696e+09 | P8: 5.2507409e+09 | Q8: 4.6390774e+09 | R8: 5.4435772e+09 | S8: 4.2652232e+09 | T8: 5.069723e+09 | U8: 3.7646862e+09 | V8: 4.569186e+09 | W8: 3.8001426e+09 | X8: 4.6046423e+09 | Y8: 3.9694377e+09 | Z8: 4.7747143e+09 | AA8: =SUM(C8,E8,G8,I8,K8,M8,O8,Q8,S8,U8,W8,Y8) -> 4.6496108e+10 | AB8: 1.0463674e+10 | AC8: ='2020'!AA8/356 -> 1.3060704e+08 | AD8: =AB8/356 -> 29392343
A9: 8 | B9: Borno | C9: 4.8399388e+09 | D9: 5.3325598e+09 | E9: 4.2536689e+09 | F9: 4.782075e+09 | G9: 4.9031417e+09 | H9: 5.4315478e+09 | I9: 4.5258675e+09 | J9: 5.0542736e+09 | K9: 4.4922686e+09 | L9: 4.5450364e+09 | M9: 5.4056906e+09 | N9: 5.5208819e+09 | O9: 5.5961356e+09 | P9: 5.6697113e+09 | Q9: 5.737817e+09 | R9: 5.8171124e+09 | S9: 5.3789863e+09 | T9: 5.4582817e+09 | U9: 4.8486014e+09 | V9: 4.9278969e+09 | W9: 4.8121593e+09 | X9: 4.8989548e+09 | Y9: 5.1124885e+09 | Z9: 5.2000608e+09 | AA9: =SUM(C9,E9,G9,I9,K9,M9,O9,Q9,S9,U9,W9,Y9) -> 5.9906764e+10 | AB9: 1.1811333e+10 | AC9: ='2020'!AA9/356 -> 1.6827743e+08 | AD9: =AB9/356 -> 33177903
A10: 9 | B10: Cross River | C10: 2.7402162e+09 | D10: 4.391059e+09 | E10: 2.1781634e+09 | F10: 3.9368545e+09 | G10: 2.7075107e+09 | H10: 4.4662018e+09 | I10: 2.4462353e+09 | J10: 4.2049264e+09 | K10: 2.2594011e+09 | L10: 3.7434176e+09 | M10: 3.0723294e+09 | N10: 4.5563459e+09 | O10: 3.1914901e+09 | P10: 4.6755066e+09 | Q10: 3.2375971e+09 | R10: 4.810932e+09 | S10: 2.9421305e+09 | T10: 4.5154654e+09 | U10: 2.4982532e+09 | V10: 4.071588e+09 | W10: 2.5232867e+09 | X10: 4.0966215e+09 | Y10: 2.7411145e+09 | Z10: 4.3152261e+09 | AA10: =SUM(C10,E10,G10,I10,K10,M10,O10,Q10,S10,U10,W10,Y10) -> 3.2537728e+10 | AB10: 1.6355595e+10 | AC10: ='2020'!AA10/356 -> 91398113 | AD10: =AB10/356 -> 45942684
A11: 10 | B11: Delta | C11: 1.6905898e+10 | D11: 1.8319116e+10 | E11: 1.7028968e+10 | F11: 1.844664e+10 | G11: 2.0116075e+10 | H11: 2.1533747e+10 | I11: 1.4376105e+10 | J11: 1.5793777e+10 | K11: 1.4296086e+10 | L11: 1.5336114e+10 | M11: 1.2261889e+10 | N11: 1.3301917e+10 | O11: 1.6945898e+10 | P11: 1.7985927e+10 | Q11: 1.3871095e+10 | R11: 1.4825087e+10 | S11: 1.5421778e+10 | T11: 1.637577e+10 | U11: 1.4032263e+10 | V11: 1.4986255e+10 | W11: 1.3481289e+10 | X11: 1.454653e+10 | Y11: 1.3450747e+10 | Z11: 1.4516765e+10 | AA11: =SUM(C11,E11,G11,I11,K11,M11,O11,Q11,S11,U11,W11,Y11) -> 1.8218809e+11 | AB11: 5.9732883e+10 | AC11: ='2020'!AA11/356 -> 5.117643e+08 | AD11: =AB11/356 -> 1.67789e+08
A12: 11 | B12: Ebonyi | C12: 3.5348881e+09 | D12: 3.9983486e+09 | E12: 3.0970974e+09 | F12: 3.5578949e+09 | G12: 3.674938e+09 | H12: 4.1360775e+09 | I12: 3.3785823e+09 | J12: 3.8339849e+09 | K12: 3.2446201e+09 | L12: 3.4542913e+09 | M12: 3.955324e+09 | N12: 4.1661517e+09 | O12: 4.0956075e+09 | P12: 4.3128305e+09 | Q12: 4.176985e+09 | R12: 4.4165051e+09 | S12: 3.9272767e+09 | T12: 4.1559292e+09 | U12: 3.4912446e+09 | V12: 3.7210516e+09 | W12: 3.5264595e+09 | X12: 3.7585813e+09 | Y12: 3.7789101e+09 | Z12: 4.0117284e+09 | AA12: =SUM(C12,E12,G12,I12,K12,M12,O12,Q12,S12,U12,W12,Y12) -> 4.3881933e+10 | AB12: 1.5896854e+10 | AC12: ='2020'!AA12/356 -> 1.2326386e+08 | AD12: =AB12/356 -> 44654083
A13: 12 | B13: Edo | C13: 5.0630668e+09 | D13: 5.8097601e+09 | E13: 4.3959129e+09 | F13: 5.2508353e+09 | G13: 5.118224e+09 | H13: 5.8971164e+09 | I13: 4.2797695e+09 | J13: 5.0586619e+09 | K13: 4.2929649e+09 | L13: 4.6858821e+09 | M13: 4.9083613e+09 | N13: 5.3012785e+09 | O13: 5.5888973e+09 | P13: 5.9818145e+09 | Q13: 5.2281111e+09 | R13: 5.6449604e+09 | S13: 4.9910534e+09 | T13: 5.4079026e+09 | U13: 4.4662026e+09 | V13: 4.8830518e+09 | W13: 4.6175083e+09 | X13: 5.0343575e+09 | Y13: 4.9494153e+09 | Z13: 5.3670414e+09 | AA13: =SUM(C13,E13,G13,I13,K13,M13,O13,Q13,S13,U13,W13,Y13) -> 5.7899487e+10 | AB13: 2.8017309e+10 | AC13: ='2020'!AA13/356 -> 1.6263901e+08 | AD13: =AB13/356 -> 78700307
... A37: 36 | B37: Zamfara | C37: 3.2964076e+09 | D37: 4.3893167e+09 | E37: 2.8400307e+09 | F37: 3.937036e+09 | G37: 3.3818433e+09 | H37: 4.4788485e+09 | I37: 3.0835091e+09 | J37: 4.1805144e+09 | K37: 2.9812386e+09 | L37: 3.7455429e+09 | M37: 3.8111634e+09 | N37: 4.5754678e+09 | O37: 3.9176241e+09 | P37: 4.6819284e+09 | Q37: 4.0624763e+09 | R37: 4.8346709e+09 | S37: 3.7503782e+09 | T37: 4.5225728e+09 | U37: 3.3217517e+09 | V37: 4.0939463e+09 | W37: 3.3515839e+09 | X37: 4.1237784e+09 | Y37: 3.5108734e+09 | Z37: 4.2838447e+09 | AA37: =SUM(C37,E37,G37,I37,K37,M37,O37,Q37,S37,U37,W37,Y37) -> 4.130888e+10 | AB37: 1.8499252e+10 | AC37: ='2020'!AA37/356 -> 1.1603618e+08 | AD37: =AB37/356 -> 51964191
A38: 37 | B38: FCT | C38: 5.7354898e+09 | E38: 5.1018556e+09 | G38: 5.7751901e+09 | I38: 5.4280467e+09 | K38: 4.8208197e+09 | M38: 5.866315e+09 | O38: 6.0255113e+09 | Q38: 6.1232132e+09 | S38: 5.7418298e+09 | U38: 5.1751126e+09 | W38: 5.079029e+09 | Y38: 5.2271278e+09 | AA38: =SUM(C38,E38,G38,I38,K38,M38,O38,Q38,S38,U38,W38,Y38) -> 6.609954e+10 | AB38: 9.2059701e+10 | AC38: ='2020'!AA38/356 -> 1.8567287e+08 | AD38: =AB38/356 -> 2.5859467e+08
AA39: =SUM(AA2:AA38) -> 2.2677231e+12

Sheet 2021
A1: S/N | B1: State | C1: January (Net) | D1: January (Gross) | E1: February (Net) | F1: February (Gross) | G1: March (Net) | H1: March (Gross) | I1: April (Net) | J1: April (Gross) | K1: May (Net) | L1: May (Gross) | M1: June (Net) | N1: June (Gross) | O1: July (Net) | P1: July (Gross) | Q1: August (Net) | R1: August (Gross) | S1: September (Net) | T1: September (Gross) | U1: October (Net) | V1: October (Gross) | W1: November (Net) | X1: November (Gross) | Y1: December (Net) | Z1: December (Gross) | AA1: Total Net | AB1: Total IGR | AC1: Total Net USD | AD1: Total IGR USD
A2: 1 | B2: Abia | C2: 4.0105197e+09 | D2: 4.4691492e+09 | E2: 3.911528e+09 | F2: 4.3701575e+09 | G2: 4.2643465e+09 | H2: 4.7229759e+09 | I2: 4.334833e+09 | J2: 4.7934625e+09 | K2: 4.3226254e+09 | L2: 4.7812549e+09 | M2: 4.5685807e+09 | N2: 5.3995533e+09 | O2: 4.8076357e+09 | P2: 5.6383915e+09 | Q2: 4.4214859e+09 | R2: 5.284192e+09 | S2: 4.7417675e+09 | T2: 5.6523162e+09 | U2: 4.2232692e+09 | V2: 5.1206179e+09 | W2: 4.4070426e+09 | X2: 5.2998307e+09 | Y2: 4.6670125e+09 | Z2: 5.4899276e+09 | AA2: =SUM(C2,E2,G2,I2,K2,M2,O2,Q2,S2,U2,W2,Y2) -> 5.2680647e+10 | AB2: 1.9578332e+10 | AC2: =AA2/399 -> 1.320317e+08 | AD2: =AA2/399 -> 1.320317e+08
A3: 2 | B3: Adamawa | C3: 4.116696e+09 | D3: 4.364854e+09 | E3: 3.7233769e+09 | F3: 3.9715349e+09 | G3: 4.336882e+09 | H3: 4.58504e+09 | I3: 4.4792407e+09 | J3: 4.7273988e+09 | K3: 4.4428876e+09 | L3: 4.6910457e+09 | M3: 4.7269933e+09 | N3: 5.3068506e+09 | O3: 4.9471696e+09 | P3: 5.5267962e+09 | Q3: 4.7744004e+09 | R3: 5.3837842e+09 | S3: 4.7821693e+09 | T3: 5.3919767e+09 | U3: 4.5379155e+09 | V3: 5.1372871e+09 | W3: 4.4587956e+09 | X3: 5.0958189e+09 | Y3: 4.8062652e+09 | Z3: 5.4425117e+09 | AA3: =SUM(C3,E3,G3,I3,K3,M3,O3,Q3,S3,U3,W3,Y3) -> 5.4132792e+10 | AB3: 1.3011611e+10 | AC3: =AA3/399 -> 1.3567116e+08 | AD3: =AA3/399 -> 1.3567116e+08
A4: 3 | B4: Akwa Ibom | C4: 1.0666405e+10 | D4: 1.1600126e+10 | E4: 9.4561093e+09 | F4: 1.038983e+10 | G4: 1.1272612e+10 | H4: 1.2206333e+10 | I4: 1.1176099e+10 | J4: 1.210982e+10 | K4: 9.5553221e+09 | L4: 1.0489043e+10 | M4: 1.3430973e+10 | N4: 1.4646923e+10 | O4: 1.4875268e+10 | P4: 1.6149319e+10 | Q4: 1.086462e+10 | R4: 1.2183571e+10 | S4: 1.5608291e+10 | T4: 1.6954925e+10 | U4: 8.9532397e+09 | V4: 1.0321865e+10 | W4: 1.4083568e+10 | X4: 1.5447296e+10 | Y4: 1.1669298e+10 | Z4: 1.3035705e+10 | AA4: =SUM(C4,E4,G4,I4,K4,M4,O4,Q4,S4,U4,W4,Y4) -> 1.4161181e+11 | AB4: 3.1396512e+10 | AC4: =AA4/399 -> 3.5491681e+08 | AD4: =AA4/399 -> 3.5491681e+08
A5: 4 | B5: Anambra | C5: 4.300928e+09 | D5: 4.4579792e+09 | E5: 4.0698815e+09 | F5: 4.2269327e+09 | G5: 4.5363849e+09 | H5: 4.6934361e+09 | I5: 4.8024167e+09 | J5: 4.9594679e+09 | K5: 4.7927391e+09 | L5: 4.9497903e+09 | M5: 5.1221057e+09 | N5: 5.5246759e+09 | O5: 5.3059845e+09 | P5: 5.7083245e+09 | Q5: 5.0649459e+09 | R5: 5.5844837e+09 | S5: 5.1913049e+09 | T5: 5.7112851e+09 | U5: 4.8775705e+09 | V5: 5.3871148e+09 | W5: 4.8453678e+09 | X5: 5.3549122e+09 | Y5: 5.2749611e+09 | Z5: 5.7152016e+09 | AA5: =SUM(C5,E5,G5,I5,K5,M5,O5,Q5,S5,U5,W5,Y5) -> 5.8184591e+10 | AB5: 3.0916675e+10 | AC5: =AA5/399 -> 1.4582604e+08 | AD5: =AA5/399 -> 1.4582604e+08
A6: 5 | B6: Bauchi | C6: 4.1673946e+09 | D6: 5.082534e+09 | E6: 3.7976799e+09 | F6: 4.7128192e+09 | G6: 4.6616999e+09 | H6: 5.3223602e+09 | I6: 4.8853364e+09 | J6: 5.5675293e+09 | K6: 4.8703527e+09 | L6: 5.6529241e+09 | M6: 5.2626121e+09 | N6: 6.3682904e+09 | O6: 5.5563459e+09 | P6: 6.7918007e+09 | Q6: 4.9796615e+09 | R6: 6.3122446e+09 | S6: 5.0583554e+09 | T6: 6.3678195e+09 | U6: 4.8032573e+09 | V6: 6.1022855e+09 | W6: 5.0739666e+09 | X6: 6.1006217e+09 | Y6: 5.0512743e+09 | Z6: 6.3124486e+09 | AA6: =SUM(C6,E6,G6,I6,K6,M6,O6,Q6,S6,U6,W6,Y6) -> 5.8167937e+10 | AB6: 1.7902448e+10 | AC6: =AA6/399 -> 1.457843e+08 | AD6: =AA6/399 -> 1.457843e+08
A7: 6 | B7: Bayelsa | C7: 6.7885335e+09 | D7: 8.730011e+09 | E7: 7.8423391e+09 | F7: 9.7838166e+09 | G7: 1.1745197e+10 | H7: 1.2746809e+10 | I7: 1.0724355e+10 | J7: 1.1725967e+10 | K7: 6.618841e+09 | L7: 8.5603185e+09 | M7: 1.4137325e+10 | N7: 1.6377233e+10 | O7: 1.2710656e+10 | P7: 1.5009775e+10 | Q7: 7.2972756e+09 | R7: 9.8616193e+09 | S7: 1.287447e+10 | T7: 1.5484596e+10 | U7: 7.0124963e+09 | V7: 8.6697093e+09 | W7: 1.2929059e+10 | X7: 1.4581962e+10 | Y7: 1.0208975e+10 | Z7: 1.1863862e+10 | AA7: =SUM(C7,E7,G7,I7,K7,M7,O7,Q7,S7,U7,W7,Y7) -> 1.2088952e+11 | AB7: 13273992304 | AC7: =AA7/399 -> 3.0298126e+08 | AD7: =AA7/399 -> 3.0298126e+08
A8: 7 | B8: Benue | C8: 3.90514e+09 | D8: 4.7964876e+09 | E8: 3.5401675e+09 | F8: 4.4648485e+09 | G8: 4.0772229e+09 | H8: 4.9852372e+09 | I8: 4.2726187e+09 | J8: 5.1806331e+09 | K8: 4.2753129e+09 | L8: 5.1833273e+09 | M8: 4.5883854e+09 | N8: 5.8544932e+09 | O8: 4.8855801e+09 | P8: 6.0736483e+09 | Q8: 4.6568112e+09 | R8: 5.878196e+09 | S8: 4.7445358e+09 | T8: 6.0211573e+09 | U8: 4.4633292e+09 | V8: 5.7262043e+09 | W8: 4.44148e+09 | X8: 5.6988931e+09 | Y8: 4857871026 | Z8: 6.0141489e+09 | AA8: =SUM(C8,E8,G8,I8,K8,M8,O8,Q8,S8,U8,W8,Y8) -> 5.2708455e+10 | AB8: 1.2601151e+10 | AC8: =AA8/399 -> 1.3210139e+08 | AD8: =AA8/399 -> 1.3210139e+08
A9: 8 | B9: Borno | C9: 5.018767e+09 | D9: 5.1035325e+09 | E9: 4.6606249e+09 | F9: 4.7453904e+09 | G9: 5.2406807e+09 | H9: 5.3254463e+09 | I9: 5.4938968e+09 | J9: 5.5786623e+09 | K9: 5.5621512e+09 | L9: 5.6469167e+09 | M9: 5.8840216e+09 | N9: 6.4475639e+09 | O9: 6.0729198e+09 | P9: 6.6361745e+09 | Q9: 5.8086887e+09 | R9: 6.3980597e+09 | S9: 5.8934937e+09 | T9: 6.4808131e+09 | U9: 5.5889865e+09 | V9: 6.1951192e+09 | W9: 5.3937379e+09 | X9: 6.0194564e+09 | Y9: 5.7987301e+09 | Z9: 6.4236718e+09 | AA9: =SUM(C9,E9,G9,I9,K9,M9,O9,Q9,S9,U9,W9,Y9) -> 6.6416699e+10 | AB9: 1.8738213e+10 | AC9: =AA9/399 -> 1.6645789e+08 | AD9: =AA9/399 -> 1.6645789e+08
A10: 9 | B10: Cross River | C10: 2.7775898e+09 | D10: 4.2621785e+09 | E10: 2.4703157e+09 | F10: 3.9549044e+09 | G10: 3.0460949e+09 | H10: 4.4621565e+09 | I10: 3.2903062e+09 | J10: 4.7063678e+09 | K10: 3.2905328e+09 | L10: 4.7065944e+09 | M10: 3.6295019e+09 | N10: 5.2924664e+09 | O10: 3.8011604e+09 | P10: 5.4638921e+09 | Q10: 3.4246018e+09 | R10: 5.2130372e+09 | S10: 3.5366116e+09 | T10: 5.3756538e+09 | U10: 3.2744023e+09 | V10: 5.1000403e+09 | W10: 3.2085276e+09 | X10: 5.0292679e+09 | Y10: 3.4745286e+09 | Z10: 5.2976284e+09 | AA10: =SUM(C10,E10,G10,I10,K10,M10,O10,Q10,S10,U10,W10,Y10) -> 3.9224174e+10 | AB10: 2.2912281e+10 | AC10: =AA10/399 -> 98306199 | AD10: =AA10/399 -> 98306199
A11: 10 | B11: Delta | C11: 1.2996335e+10 | D11: 1.4021482e+10 | E11: 1.6888218e+10 | F11: 1.7906699e+10 | G11: 1.638287e+10 | H11: 1.7401351e+10 | I11: 1.5445266e+10 | J11: 1.6463747e+10 | K11: 1.2692862e+10 | L11: 1.3711342e+10 | M11: 1.9065257e+10 | N11: 2.0658773e+10 | O11: 1.9980675e+10 | P11: 2.1573956e+10 | Q11: 1.3597147e+10 | R11: 1.5231424e+10 | S11: 2.1144151e+10 | T11: 2.2829426e+10 | U11: 1.0541087e+10 | V11: 1.2212928e+10 | W11: 1.8524055e+10 | X11: 2.0217028e+10 | Y11: 1.4873439e+10 | Z11: 1.6568803e+10 | AA11: =SUM(C11,E11,G11,I11,K11,M11,O11,Q11,S11,U11,W11,Y11) -> 1.9213136e+11 | AB11: 8.0203624e+10 | AC11: =AA11/399 -> 4.8153224e+08 | AD11: =AA11/399 -> 4.8153224e+08
A12: 11 | B12: Ebonyi | C12: 3.7776798e+09 | D12: 3.9869979e+09 | E12: 3.458883e+09 | F12: 3.698309e+09 | G12: 3955052605 | H12: 4195108667 | I12: 4.0196185e+09 | J12: 4.2621862e+09 | K12: 4.1331894e+09 | L12: 4.3718012e+09 | M12: 4.3708249e+09 | N12: 4.8732458e+09 | O12: 4.4907247e+09 | P12: 4.9948838e+09 | Q12: 4.2738159e+09 | R12: 4.8223726e+09 | S12: 4.324644e+09 | T12: 4.8792456e+09 | U12: 4.1505163e+09 | V12: 4.6831249e+09 | W12: 4.1775771e+09 | X12: 4.7161916e+09 | Y12: 4.3456659e+09 | Z12: 4.8854062e+09 | AA12: =SUM(C12,E12,G12,I12,K12,M12,O12,Q12,S12,U12,W12,Y12) -> 4.9478192e+10 | AB12: 1.3752313e+10 | AC12: =AA12/399 -> 1.2400549e+08 | AD12: =AA12/399 -> 1.2400549e+08
A13: 12 | B13: Edo | C13: 4.6922413e+09 | D13: 5.0766761e+09 | E13: 5.1155413e+09 | F13: 5.4999761e+09 | G13: 5.6527203e+09 | H13: 6.037155e+09 | I13: 5.7367635e+09 | J13: 6.1211982e+09 | K13: 4.9697831e+09 | L13: 5.4542178e+09 | M13: 6.762368e+09 | N13: 7.6357191e+09 | O13: 6.5480655e+09 | P13: 7.379302e+09 | Q13: 5.2848197e+09 | R13: 6.1784115e+09 | S13: 5.9969749e+09 | T13: 7.3444069e+09 | U13: 4.4969078e+09 | V13: 5.7730419e+09 | W13: 5.6295083e+09 | X13: 6.9010883e+09 | Y13: 5.366581e+09 | Z13: 6.6403004e+09 | AA13: =SUM(C13,E13,G13,I13,K13,M13,O13,Q13,S13,U13,W13,Y13) -> 6.6252275e+10 | AB13: 4.2427205e+10 | AC13: =AA13/399 -> 1.660458e+08 | AD13: =AA13/399 -> 1.660458e+08
